<robot name="scara_robot">
  <link name="base_link">
    <visual>
      <geometry>
        <cylinder length="0.1" radius="0.15"/>
      </geometry>
      <material name="white">
        <color rgba="1 1 1 1"/>
      </material>
    </visual>
   
    <collision>
      <origin xyz="0 0 0" rpy="0 0 0" />
      <geometry>
          <cylinder length="0.1" radius="0.05"/>
      </geometry>
  </collision>

  <inertial>
      <origin xyz="0 0 0" rpy="0 0 0"/>
      <mass value="1"/>
      <inertia
          ixx="1.0" ixy="0.0" ixz="0.0"
          iyy="1.0" iyz="0.0"
          izz="1.0"/>
  </inertial>
  </link>

  <link name="link1">
    <visual>
      <geometry>
        <cylinder length="0.25" radius="0.075"/>
      </geometry>
      <material name="black">
        <color rgba="0 0 0 1"/>
      </material>
    </visual>
   
    <collision>
      <origin xyz="0 0 0" rpy="0 0 0" />
      <geometry>
          <cylinder length="0.2" radius="0.05"/>
      </geometry>
  </collision>

  <inertial>
      <origin xyz="0 0 0" rpy="0 0 0"/>
      <mass value="1"/>
      <inertia
          ixx="1.0" ixy="0.0" ixz="0.0"
          iyy="1.0" iyz="0.0"
          izz="1.0"/>
  </inertial>
  </link>

 <link name="link4">
    <visual>
      <geometry>
        <box size="0.05 0.05 0.2"/>
      </geometry>
      <material name="red">
        <color rgba="1 0 0 1"/>
      </material>
    </visual>
   
    <collision>
      <origin xyz="0 0 0" rpy="0 0 0" />
      <geometry>
          <cylinder size="0.05 0.05 0.1" />
      </geometry>
  </collision>
  </link>
<link name="link5">
    <visual>
      <geometry>
        <box size="0.15 0.05 0.05"/>
      </geometry>
      <material name="red">
        <color rgba="1 0 0 1"/>
      </material>
    </visual>
  </link>

<link name="link6">
    <visual>
      <geometry>
        <box size="0.05 0.05 0.05"/>
      </geometry>
      <material name="red">
        <color rgba="1 0 0 1"/>
      </material>
    </visual>
  </link>

  <link name="link2">
    <visual>
      <geometry>
        <cylinder length="0.1" radius="0.075"/>
      </geometry>
        <material name="black">
          <color rgba="0 0 0 1"/>
      </material>
    </visual>
    <collision>
      <origin xyz="0 0 0" rpy="0 0 0" />
      <geometry>
          <cylinder length="0.15" radius="0.05"/>
      </geometry>
      
  </collision>

  <inertial>
      <origin xyz="0 0 0" rpy="0 0 0"/>
      <mass value="1"/>
      <inertia
          ixx="1.0" ixy="0.0" ixz="0.0"
          iyy="1.0" iyz="0.0"
          izz="1.0"/>
  </inertial>
  </link>

  <link name="link3">
    <visual>
      <geometry>
        <box size="0.05 0.05 0.1"/>
      </geometry>
      <material name="black">
        <color rgba="0 0 0 1"/>
      </material>
    </visual>
   
    <collision>
      <origin xyz="0 0 0" rpy="0 0 0" />
      <geometry>
          <cylinder size="0.05 0.05 0.1" />
      </geometry>
  </collision>

  <inertial>
      <origin xyz="0 0 0" rpy="0 0 0"/>
      <mass value="1"/>
      <inertia
          ixx="1.0" ixy="0.0" ixz="0.0"
          iyy="1.0" iyz="0.0"
          izz="1.0"/>
  </inertial>
  </link>

  <joint name="joint1" type="revolute">
    <parent link="base_link"/>
    <child link="link1" />
    <origin xyz="0 0 0.1" rpy="0 0 0"/>
    <axis xyz="0 0 1"/>
    <limit effort="50" velocity="9.5" lower="-1.5" upper="1.5" />
  </joint>

  <joint name="joint2" type="revolute">
    <parent link="link1"/>
    <child link="link2" />
    <origin xyz="0.2 0 0.2" rpy="0 0 0"/>
    <axis xyz="0 0 1"/>
    <limit effort="50" velocity="9.5" lower="-1.5" upper="1.5" />
  </joint>

  <joint name="joint3" type="prismatic">
    <parent link="link2"/>
    <child link="link3" />
    <origin xyz="0.15 0 0" rpy="0 0 0"/>
    <axis xyz="0 0 1"/>
    <limit effort="50" velocity="9.5" lower="-0.1" upper="0.1" />
  </joint>

 	<joint name="Joint4" type="fixed">
    	<parent link="link1"/>
    	<child link="link4"/>
    	 <origin xyz="0 0 0.15" rpy="0 0 0"/>
    <axis xyz="0 0 1"/>
	</joint>
	<joint name="Joint5" type="fixed">
    	<parent link="link4"/>
    	<child link="link5"/>
    	 <origin xyz="0.05 0 0.05" rpy="0 0 0"/>
    <axis xyz="0 0 1"/>
	</joint>
	<joint name="Joint6" type="fixed">
    	<parent link="link2"/>
    	<child link="link6"/>
    	 <origin xyz="0.1 0 0" rpy="0 0 0"/>
    <axis xyz="0 0 1"/>
	</joint>
</robot>